(dp1
S'output'
p2
S'<type \'exceptions.RuntimeError\'> Failure to connect, tried 5 times:\nTraceback (most recent call last):\n  File "/home/yalex/web2py/gluon/packages/dal/pydal/base.py", line 454, in __init__\n    self._adapter = adapter(**kwargs)\n  File "/home/yalex/web2py/gluon/packages/dal/pydal/adapters/__init__.py", line 40, in __call__\n    obj = super(AdapterMeta, cls).__call__(*args, **kwargs)\n  File "/home/yalex/web2py/gluon/packages/dal/pydal/adapters/base.py", line 368, in __init__\n    super(SQLAdapter, self).__init__(*args, **kwargs)\n  File "/home/yalex/web2py/gluon/packages/dal/pydal/adapters/base.py", line 52, in __init__\n    self.reconnect()\n  File "/home/yalex/web2py/gluon/packages/dal/pydal/connection.py", line 152, in reconnect\n    self.connection = self.connector()\n  File "/home/yalex/web2py/gluon/packages/dal/pydal/adapters/mysql.py", line 52, in connector\n    return self.driver.connect(**self.driver_args)\n  File "/home/yalex/web2py/gluon/contrib/pymysql/__init__.py", line 90, in Connect\n    return Connection(*args, **kwargs)\n  File "/home/yalex/web2py/gluon/contrib/pymysql/connections.py", line 688, in __init__\n    self.connect()\n  File "/home/yalex/web2py/gluon/contrib/pymysql/connections.py", line 937, in connect\n    raise exc\nOperationalError: (2003, "Can\'t connect to MySQL server on \'192.168.1.181\' ([Errno 110] Connection timed out)")\n'
p3
sS'layer'
p4
S'/home/yalex/web2py/applications/asterisk/models/db.py'
p5
sS'code'
p6
S'<code object <module> at 0x7f58c494e2b0, file "/home/yalex/web2py/applications/asterisk/models/db.py", line 12>'
p7
sS'snapshot'
p8
(dp9
sS'traceback'
p10
S'Traceback (most recent call last):\n  File "/home/yalex/web2py/gluon/restricted.py", line 219, in restricted\n    exec(ccode, environment)\n  File "/home/yalex/web2py/applications/asterisk/models/db.py", line 16, in <module>\n    db = DAL("mysql://asterisk:asterisk@localhost/asterisk")\n  File "/home/yalex/web2py/gluon/packages/dal/pydal/base.py", line 169, in __call__\n    obj = super(MetaDAL, cls).__call__(*args, **kwargs)\n  File "/home/yalex/web2py/gluon/packages/dal/pydal/base.py", line 474, in __init__\n    "Failure to connect, tried %d times:\\n%s" % (attempts, tb)\nRuntimeError: Failure to connect, tried 5 times:\nTraceback (most recent call last):\n  File "/home/yalex/web2py/gluon/packages/dal/pydal/base.py", line 454, in __init__\n    self._adapter = adapter(**kwargs)\n  File "/home/yalex/web2py/gluon/packages/dal/pydal/adapters/__init__.py", line 40, in __call__\n    obj = super(AdapterMeta, cls).__call__(*args, **kwargs)\n  File "/home/yalex/web2py/gluon/packages/dal/pydal/adapters/base.py", line 368, in __init__\n    super(SQLAdapter, self).__init__(*args, **kwargs)\n  File "/home/yalex/web2py/gluon/packages/dal/pydal/adapters/base.py", line 52, in __init__\n    self.reconnect()\n  File "/home/yalex/web2py/gluon/packages/dal/pydal/connection.py", line 152, in reconnect\n    self.connection = self.connector()\n  File "/home/yalex/web2py/gluon/packages/dal/pydal/adapters/mysql.py", line 52, in connector\n    return self.driver.connect(**self.driver_args)\n  File "/home/yalex/web2py/gluon/contrib/pymysql/__init__.py", line 90, in Connect\n    return Connection(*args, **kwargs)\n  File "/home/yalex/web2py/gluon/contrib/pymysql/connections.py", line 688, in __init__\n    self.connect()\n  File "/home/yalex/web2py/gluon/contrib/pymysql/connections.py", line 937, in connect\n    raise exc\nOperationalError: (2003, "Can\'t connect to MySQL server on \'192.168.1.181\' ([Errno 110] Connection timed out)")\n\n'
p11
s.